Exception:
Traceback (most recent call last):
  File "/cm/shared/apps/python/3.5.2/lib/python3.5/site-packages/pip/basecommand.py", line 215, in main
    status = self.run(options, args)
  File "/cm/shared/apps/python/3.5.2/lib/python3.5/site-packages/pip/commands/uninstall.py", line 76, in run
    requirement_set.uninstall(auto_confirm=options.yes)
  File "/cm/shared/apps/python/3.5.2/lib/python3.5/site-packages/pip/req/req_set.py", line 346, in uninstall
    req.uninstall(auto_confirm=auto_confirm)
  File "/cm/shared/apps/python/3.5.2/lib/python3.5/site-packages/pip/req/req_install.py", line 754, in uninstall
    paths_to_remove.remove(auto_confirm)
  File "/cm/shared/apps/python/3.5.2/lib/python3.5/site-packages/pip/req/req_uninstall.py", line 103, in remove
    response = ask('Proceed (y/n)? ', ('y', 'n'))
  File "/cm/shared/apps/python/3.5.2/lib/python3.5/site-packages/pip/utils/__init__.py", line 158, in ask
    response = input(message)
EOFError: EOF when reading a line
I tensorflow/stream_executor/dso_loader.cc:111] successfully opened CUDA library libcublas.so locally
I tensorflow/stream_executor/dso_loader.cc:111] successfully opened CUDA library libcudnn.so locally
I tensorflow/stream_executor/dso_loader.cc:111] successfully opened CUDA library libcufft.so locally
I tensorflow/stream_executor/dso_loader.cc:111] successfully opened CUDA library libcuda.so.1 locally
I tensorflow/stream_executor/dso_loader.cc:111] successfully opened CUDA library libcurand.so locally
/cm/local/apps/slurm/var/spool/job3473950/slurm_script: line 38: 29954 Segmentation fault      python -m basic.cli --mode train --noload --out_base_dir "out/nqa-sq-100/" --joint_ratio 1.0 --batch_size 60 --num_steps 20000 -device /gpu:0 --device_type gpu --num_gpus 1
