Exception:
Traceback (most recent call last):
  File "/cm/shared/apps/python/3.5.2/lib/python3.5/site-packages/pip/basecommand.py", line 215, in main
    status = self.run(options, args)
  File "/cm/shared/apps/python/3.5.2/lib/python3.5/site-packages/pip/commands/uninstall.py", line 76, in run
    requirement_set.uninstall(auto_confirm=options.yes)
  File "/cm/shared/apps/python/3.5.2/lib/python3.5/site-packages/pip/req/req_set.py", line 346, in uninstall
    req.uninstall(auto_confirm=auto_confirm)
  File "/cm/shared/apps/python/3.5.2/lib/python3.5/site-packages/pip/req/req_install.py", line 754, in uninstall
    paths_to_remove.remove(auto_confirm)
  File "/cm/shared/apps/python/3.5.2/lib/python3.5/site-packages/pip/req/req_uninstall.py", line 103, in remove
    response = ask('Proceed (y/n)? ', ('y', 'n'))
  File "/cm/shared/apps/python/3.5.2/lib/python3.5/site-packages/pip/utils/__init__.py", line 158, in ask
    response = input(message)
EOFError: EOF when reading a line
I tensorflow/stream_executor/dso_loader.cc:111] successfully opened CUDA library libcublas.so locally
I tensorflow/stream_executor/dso_loader.cc:111] successfully opened CUDA library libcudnn.so locally
I tensorflow/stream_executor/dso_loader.cc:111] successfully opened CUDA library libcufft.so locally
I tensorflow/stream_executor/dso_loader.cc:111] successfully opened CUDA library libcuda.so.1 locally
I tensorflow/stream_executor/dso_loader.cc:111] successfully opened CUDA library libcurand.so locally
I tensorflow/core/common_runtime/gpu/gpu_device.cc:951] Found device 0 with properties: 
name: Tesla M40 24GB
major: 5 minor: 2 memoryClockRate (GHz) 1.112
pciBusID 0000:81:00.0
Total memory: 22.43GiB
Free memory: 22.32GiB
W tensorflow/stream_executor/cuda/cuda_driver.cc:572] creating context when one is currently active; existing: 0x63664b00
I tensorflow/core/common_runtime/gpu/gpu_device.cc:951] Found device 1 with properties: 
name: Tesla M40 24GB
major: 5 minor: 2 memoryClockRate (GHz) 1.112
pciBusID 0000:82:00.0
Total memory: 22.43GiB
Free memory: 22.32GiB
I tensorflow/core/common_runtime/gpu/gpu_device.cc:972] DMA: 0 1 
I tensorflow/core/common_runtime/gpu/gpu_device.cc:982] 0:   Y Y 
I tensorflow/core/common_runtime/gpu/gpu_device.cc:982] 1:   Y Y 
I tensorflow/core/common_runtime/gpu/gpu_device.cc:1041] Creating TensorFlow device (/gpu:0) -> (device: 0, name: Tesla M40 24GB, pci bus id: 0000:81:00.0)
I tensorflow/core/common_runtime/gpu/gpu_device.cc:1041] Creating TensorFlow device (/gpu:1) -> (device: 1, name: Tesla M40 24GB, pci bus id: 0000:82:00.0)
  0%|          | 0/10000 [00:00<?, ?it/s]I tensorflow/core/common_runtime/gpu/pool_allocator.cc:245] PoolAllocator: After 121356 get requests, put_count=43725 evicted_count=1000 eviction_rate=0.0228702 and unsatisfied allocation rate=0.648761
I tensorflow/core/common_runtime/gpu/pool_allocator.cc:257] Raising pool_size_limit_ from 100 to 110
I tensorflow/core/common_runtime/gpu/pool_allocator.cc:245] PoolAllocator: After 7236 get requests, put_count=13245 evicted_count=6000 eviction_rate=0.453001 and unsatisfied allocation rate=0.000690989
I tensorflow/core/common_runtime/gpu/pool_allocator.cc:245] PoolAllocator: After 18120 get requests, put_count=34112 evicted_count=16000 eviction_rate=0.469043 and unsatisfied allocation rate=0.00121413
I tensorflow/core/common_runtime/gpu/pool_allocator.cc:245] PoolAllocator: After 28994 get requests, put_count=54981 evicted_count=26000 eviction_rate=0.472891 and unsatisfied allocation rate=0.000931227
I tensorflow/core/common_runtime/gpu/pool_allocator.cc:245] PoolAllocator: After 39894 get requests, put_count=75874 evicted_count=36000 eviction_rate=0.474471 and unsatisfied allocation rate=0.000852258
I tensorflow/core/common_runtime/gpu/pool_allocator.cc:245] PoolAllocator: After 50821 get requests, put_count=96789 evicted_count=46000 eviction_rate=0.475261 and unsatisfied allocation rate=0.000905138
I tensorflow/core/common_runtime/gpu/pool_allocator.cc:245] PoolAllocator: After 62108 get requests, put_count=118069 evicted_count=56000 eviction_rate=0.474299 and unsatisfied allocation rate=0.000853352
I tensorflow/core/common_runtime/gpu/pool_allocator.cc:245] PoolAllocator: After 73634 get requests, put_count=139593 evicted_count=66000 eviction_rate=0.472803 and unsatisfied allocation rate=0.000746938
  0%|          | 1/10000 [00:10<29:31:24, 10.63s/it]Traceback (most recent call last):
  File "/cm/shared/apps/python/3.5.2/lib/python3.5/runpy.py", line 184, in _run_module_as_main
    "__main__", mod_spec)
  File "/cm/shared/apps/python/3.5.2/lib/python3.5/runpy.py", line 85, in _run_code
    exec(code, run_globals)
  File "/home/usaxena/work/s18/696/bidaf/basic/cli.py", line 111, in <module>
    tf.app.run()
  File "/home/usaxena/.local/lib/python3.5/site-packages/tensorflow/python/platform/app.py", line 30, in run
    sys.exit(main(sys.argv[:1] + flags_passthrough))
  File "/home/usaxena/work/s18/696/bidaf/basic/cli.py", line 108, in main
    m(config)
  File "/home/usaxena/work/s18/696/bidaf/basic/main.py", line 23, in main
    _train(config)
  File "/home/usaxena/work/s18/696/bidaf/basic/main.py", line 99, in _train
    loss, summary, train_op = trainer.step(sess, batches, get_summary=get_summary)
  File "/home/usaxena/work/s18/696/bidaf/basic/trainer.py", line 65, in step
    feed_dict.update(model.get_feed_dict(ds, True))
  File "/home/usaxena/work/s18/696/bidaf/basic/model.py", line 316, in get_feed_dict
    y[i, j, k] = True
IndexError: index 159 is out of bounds for axis 2 with size 113
